Workbook

Sheet 表紙
K14: VRMブループリンター
K15: 汎用機能
K16: 第1.0版
K34: 作成日 | R34: 46020
K35: 作成者 | R35: ***

Sheet 変更履歴
A1: 変更履歴 | I1: システム名 | P1: =表紙!K14 -> VRMブループリンター | AA1: 作者名 | AE1: =表紙!R35 -> ***
I2: サブシステム名 | AA2: 作成日 | AE2: =表紙!R34 -> 46020
D5: No | F5: 対応 | I5: 更新日 | N5: 更新者 | S5: 更新内容 | AM5: 備考
D6: 1 | F6: 新規 | I6: =AE2 -> 46020 | N6: =AE1 -> *** | S6: 新規作成

Sheet 00.汎用機能
A1: =表紙!$K$15 -> 汎用機能 | I1: システム名 | P1: =表紙!K14 -> VRMブループリンター | AA1: 作者名 | AE1: =変更履歴!AE1 -> *** | AM1: 更新者名
I2: サブシステム名 | P2: =表紙!K15 -> 汎用機能 | AA2: 作成日 | AE2: =変更履歴!AE2 -> 46020 | AM2: 更新日
A3: View | C3: Controller | E3: Service | G3: 処理内容
H5: 物理名
I6: viewGeneralPurpose
I7: controllerGeneralPurpose
I8: serviceGeneralPurpose
H9: 概要
I10: 共通的なメニュー制御、設定の保存・読込、
I11: モデルのエクスポートなどを担当

Sheet 01.初期処理
A1: =表紙!$K$15 -> 汎用機能 | I1: システム名 | P1: =表紙!K14 -> VRMブループリンター | AA1: 作者名 | AE1: =変更履歴!AE1 -> *** | AM1: 更新者名
I2: サブシステム名 | P2: モデル情報機能 | AA2: 作成日 | AE2: =変更履歴!AE2 -> 46020 | AM2: 更新日
A3: View | C3: Controller | E3: Service | G3: 処理内容
H5: 物理名
I6: Start
H7: 概要
I8: 初期処理
H10: 1 | I10: バインド
I11: (1) | K11: メインメニューをバインド
I12: (2) | K12: サブメニューをバインド
H14: 2 | I14: コールバック登録
I15: (1) | K15: 機能選択ドロップダウンリストのコールバック登録
I16: (2) | K16: セーブ・ロードボタンのコールバック登録
I17: (3) | K17: モデルプレビューボタンのコールバック登録
I18: (4) | K18: モデル選択ボタンのコールバック登録
I19: (5) | K19: エクポートボタンのコールバック登録
N25: No | Q25: データ型
N26: 引数1 | Q26: UIDocument
M27: 3 | N27: カメラコントロールをtrue(操作可能)に設定
J28: ② | K28: 情報ボタン処理
K29: A. | L29: 情報サブメニューを表示
K30: B. | L30: モデル情報をテキストフィールドに設定
K31: C. | L31: 各テキストフィールドにイベントハンドラを設定
L32: ボタン | S32: イベント内容
L33: タイトル | S33: 変更内容をモデル情報.タイトルに設定
L34: バージョン | S34: 変更内容をモデル情報.バージョンに設定
L35: 作者 | S35: 変更内容をモデル情報.作者に設定
L36: 連絡情報 | S36: 変更内容をモデル情報.連絡情報に設定
L37: 参照 | S37: 変更内容をモデル情報.参照に設定
J38: ③ | K38: 人格許容範囲ボタン処理
K39: A. | L39: 情報サブメニューを表示
K40: B. | L40: 人格許容範囲設定をドロップダウンフィールド、テキストフィールドに設定
K41: C. | L41: 各エレメントにイベントハンドラを設定
L42: エレメント | S42: イベント内容
L43: 人格の許容範囲 | S43: 変更内容をモデル情報.人格許諾範囲に設定
L44: 暴力表現の許可 | S44: 変更内容をモデル情報.バージョンに設定
L45: 性的表現の許可 | S45: 変更内容をモデル情報.作者に設定
L46: 商用利用の許可 | S46: 変更内容をモデル情報.連絡情報に設定
L47: OtherPertmissionUrl | S47: 変更内容をモデル情報.参照に設定
J48: ④ | K48: 再配布改変許容範囲ボタン処理
...

Sheet 03.サムネイル反映処理
A1: =表紙!$K$15 -> 汎用機能 | I1: システム名 | P1: =表紙!K14 -> VRMブループリンター | AA1: 作者名 | AE1: =変更履歴!AE1 -> *** | AM1: 更新者名
I2: サブシステム名 | P2: モデル情報機能 | AA2: 作成日 | AE2: =変更履歴!AE2 -> 46020 | AM2: 更新日
A3: View | C3: Controller | E3: Service | G3: 処理内容
H5: 物理名
I6: setThimbanail
H7: 概要
I8: サムネイル画像の読み込みと反映。
I11: No | L11: データ型
I12: 引数1 | L12: UIDocument
H13: 1 | I13: サムネイル反映処理
I14: (1) | K14: 初期化処理
J15: ① | K15: モデル情報オブジェクトの初期化、取得。
I16: (2) | K16: UI要素取得
J17: ① | K17: サムネイル表示用VisualElementを取得
I18: (3) | K18: ファイル選択処理
J19: ① | K19: システムファイルダイアログを使用して画像ファイルを選択
K20: 処理 | Q20: データ形式
K21: ファイル読込 | Q21: .png
Q22: .jpg
J23: ② | K23: 選択された画像ファイルをバイト配列として読み込み
I24: (4) | K24: テクスチャ設定
J25: ① | K25: 読み込んだ画像データをTexture2Dに変換しUIに設定
J26: ② | K26: モデル情報.サムネイルデータに読み込んだ画像データを保存

Sheet 04.LicenseのInt変換
A1: =表紙!$K$15 -> 汎用機能 | I1: システム名 | P1: =表紙!K14 -> VRMブループリンター | AA1: 作者名 | AE1: =変更履歴!AE1 -> *** | AM1: 更新者名
I2: サブシステム名 | P2: モデル情報機能 | AA2: 作成日 | AE2: =変更履歴!AE2 -> 46020 | AM2: 更新日
A3: View | C3: Controller | E3: Service | G3: 処理内容
H5: 物理名
I6: getAllowedUserUssageLicenseToInt
H7: 概要
I8: ライセンス文字列の数値変換。
I11: No | L11: データ型
I12: 引数1 | L12: string
H13: 1 | I13: 変換処理
I14: (1) | K14: 初期設定
J15: ① | K15: 内部変数に0を設定。
K16: No | N16: データ型
K17: resultInt | N17: int
I18: (2) | K18: 変換処理
K19: 引数1の内容から判定し下記の通り設定する
K20: 条件 | V20: 処理
K21: "Only Author" | V21: resultInt = 0
K22: "Explicitly Licensed Parson" | V22: resultInt = 1
K23: "Everyone" | V23: resultInt = 2
K24: "Disallow" | V24: resultInt = 0
K25: "Allow" | V25: resultInt = 1
I27: (3) | K27: 処理終了
J28: ① | K28: 内部変数を返却する。
K29: No | N29: データ型
K30: resultInt | N30: int
